2016-08-31 14:44:45,295 INFO: microblog startup [in /Users/tao/Study/projects/microblog_flask/app/__init__.py:38]
2016-08-31 14:47:12,223 INFO: microblog startup [in /Users/tao/Study/projects/microblog_flask/app/__init__.py:38]
2016-08-31 14:47:16,471 ERROR: Exception on /edit [GET] [in /Users/tao/.virtualenvs/flask/lib/python2.7/site-packages/flask/app.py:1587]
Traceback (most recent call last):
  File "/Users/tao/.virtualenvs/flask/lib/python2.7/site-packages/flask/app.py", line 1988, in wsgi_app
    response = self.full_dispatch_request()
  File "/Users/tao/.virtualenvs/flask/lib/python2.7/site-packages/flask/app.py", line 1641, in full_dispatch_request
    rv = self.handle_user_exception(e)
  File "/Users/tao/.virtualenvs/flask/lib/python2.7/site-packages/flask/app.py", line 1544, in handle_user_exception
    reraise(exc_type, exc_value, tb)
  File "/Users/tao/.virtualenvs/flask/lib/python2.7/site-packages/flask/app.py", line 1639, in full_dispatch_request
    rv = self.dispatch_request()
  File "/Users/tao/.virtualenvs/flask/lib/python2.7/site-packages/flask/app.py", line 1625, in dispatch_request
    return self.view_functions[rule.endpoint](**req.view_args)
  File "/Users/tao/.virtualenvs/flask/lib/python2.7/site-packages/flask_login.py", line 792, in decorated_view
    return func(*args, **kwargs)
  File "/Users/tao/Study/projects/microblog_flask/app/views.py", line 109, in edit
    form.nickname.data = g.user.nickname
AttributeError: 'EditForm' object has no attribute 'nickname'
2016-08-31 14:48:41,858 ERROR: Exception on /edit [GET] [in /Users/tao/.virtualenvs/flask/lib/python2.7/site-packages/flask/app.py:1587]
Traceback (most recent call last):
  File "/Users/tao/.virtualenvs/flask/lib/python2.7/site-packages/flask/app.py", line 1988, in wsgi_app
    response = self.full_dispatch_request()
  File "/Users/tao/.virtualenvs/flask/lib/python2.7/site-packages/flask/app.py", line 1641, in full_dispatch_request
    rv = self.handle_user_exception(e)
  File "/Users/tao/.virtualenvs/flask/lib/python2.7/site-packages/flask/app.py", line 1544, in handle_user_exception
    reraise(exc_type, exc_value, tb)
  File "/Users/tao/.virtualenvs/flask/lib/python2.7/site-packages/flask/app.py", line 1639, in full_dispatch_request
    rv = self.dispatch_request()
  File "/Users/tao/.virtualenvs/flask/lib/python2.7/site-packages/flask/app.py", line 1625, in dispatch_request
    return self.view_functions[rule.endpoint](**req.view_args)
  File "/Users/tao/.virtualenvs/flask/lib/python2.7/site-packages/flask_login.py", line 792, in decorated_view
    return func(*args, **kwargs)
  File "/Users/tao/Study/projects/microblog_flask/app/views.py", line 109, in edit
    form.nickname.data = g.user.nickname
AttributeError: 'EditForm' object has no attribute 'nickname'
2016-08-31 15:02:43,359 INFO: microblog startup [in /Users/tao/Study/projects/microblog_flask/app/__init__.py:38]
2016-08-31 15:04:09,443 INFO: microblog startup [in /Users/tao/Study/projects/microblog_flask/app/__init__.py:38]
2016-08-31 15:49:29,117 INFO: microblog startup [in /Users/tao/Study/projects/microblog_flask/app/__init__.py:38]
2016-08-31 15:59:01,224 INFO: microblog startup [in /Users/tao/Study/projects/microblog_flask/app/__init__.py:38]
2016-08-31 16:06:42,546 INFO: microblog startup [in /Users/tao/Study/projects/microblog_flask/app/__init__.py:38]
2016-08-31 16:07:24,641 INFO: microblog startup [in /Users/tao/Study/projects/microblog_flask/app/__init__.py:38]
2016-08-31 16:27:28,953 INFO: microblog startup [in /Users/tao/Study/projects/microblog_flask/app/__init__.py:38]
2016-08-31 16:27:38,288 ERROR: Exception on /edit [GET] [in /Users/tao/.virtualenvs/flask/lib/python2.7/site-packages/flask/app.py:1587]
Traceback (most recent call last):
  File "/Users/tao/.virtualenvs/flask/lib/python2.7/site-packages/flask/app.py", line 1988, in wsgi_app
    response = self.full_dispatch_request()
  File "/Users/tao/.virtualenvs/flask/lib/python2.7/site-packages/flask/app.py", line 1641, in full_dispatch_request
    rv = self.handle_user_exception(e)
  File "/Users/tao/.virtualenvs/flask/lib/python2.7/site-packages/flask/app.py", line 1544, in handle_user_exception
    reraise(exc_type, exc_value, tb)
  File "/Users/tao/.virtualenvs/flask/lib/python2.7/site-packages/flask/app.py", line 1639, in full_dispatch_request
    rv = self.dispatch_request()
  File "/Users/tao/.virtualenvs/flask/lib/python2.7/site-packages/flask/app.py", line 1625, in dispatch_request
    return self.view_functions[rule.endpoint](**req.view_args)
  File "/Users/tao/.virtualenvs/flask/lib/python2.7/site-packages/flask_login.py", line 792, in decorated_view
    return func(*args, **kwargs)
  File "/Users/tao/Study/projects/microblog_flask/app/views.py", line 109, in edit
    flash('Your changes have been saved.')
AttributeError: 'EditForm' object has no attribute 'nickname'
2016-08-31 16:29:07,738 INFO: microblog startup [in /Users/tao/Study/projects/microblog_flask/app/__init__.py:38]
2016-08-31 16:30:12,380 INFO: microblog startup [in /Users/tao/Study/projects/microblog_flask/app/__init__.py:38]
2016-08-31 16:33:37,781 INFO: microblog startup [in /Users/tao/Study/projects/microblog_flask/app/__init__.py:38]
2016-09-01 09:32:21,333 INFO: microblog startup [in /Users/tao/Study/projects/microblog_flask/app/__init__.py:38]
2016-09-01 09:40:05,608 INFO: microblog startup [in /Users/tao/Study/projects/microblog_flask/app/__init__.py:38]
2016-09-01 09:41:53,563 INFO: microblog startup [in /Users/tao/Study/projects/microblog_flask/app/__init__.py:38]
2016-09-01 09:42:02,909 ERROR: Exception on /index [GET] [in /Users/tao/.virtualenvs/flask/lib/python2.7/site-packages/flask/app.py:1587]
Traceback (most recent call last):
  File "/Users/tao/.virtualenvs/flask/lib/python2.7/site-packages/flask/app.py", line 1988, in wsgi_app
    response = self.full_dispatch_request()
  File "/Users/tao/.virtualenvs/flask/lib/python2.7/site-packages/flask/app.py", line 1641, in full_dispatch_request
    rv = self.handle_user_exception(e)
  File "/Users/tao/.virtualenvs/flask/lib/python2.7/site-packages/flask/app.py", line 1544, in handle_user_exception
    reraise(exc_type, exc_value, tb)
  File "/Users/tao/.virtualenvs/flask/lib/python2.7/site-packages/flask/app.py", line 1637, in full_dispatch_request
    rv = self.preprocess_request()
  File "/Users/tao/.virtualenvs/flask/lib/python2.7/site-packages/flask/app.py", line 1837, in preprocess_request
    rv = func()
  File "/Users/tao/Study/projects/microblog_flask/app/views.py", line 18, in before_request
    if g.user.is_authenticated:
  File "/Users/tao/.virtualenvs/flask/lib/python2.7/site-packages/werkzeug/local.py", line 343, in __getattr__
    return getattr(self._get_current_object(), name)
  File "/Users/tao/.virtualenvs/flask/lib/python2.7/site-packages/werkzeug/local.py", line 302, in _get_current_object
    return self.__local()
  File "/Users/tao/.virtualenvs/flask/lib/python2.7/site-packages/flask_login.py", line 47, in <lambda>
    current_user = LocalProxy(lambda: _get_user())
  File "/Users/tao/.virtualenvs/flask/lib/python2.7/site-packages/flask_login.py", line 858, in _get_user
    current_app.login_manager._load_user()
  File "/Users/tao/.virtualenvs/flask/lib/python2.7/site-packages/flask_login.py", line 389, in _load_user
    return self.reload_user()
  File "/Users/tao/.virtualenvs/flask/lib/python2.7/site-packages/flask_login.py", line 351, in reload_user
    user = self.user_callback(user_id)
  File "/Users/tao/Study/projects/microblog_flask/app/views.py", line 12, in load_user
    return User.query.get(int(id))
  File "/Users/tao/.virtualenvs/flask/lib/python2.7/site-packages/sqlalchemy/orm/query.py", line 831, in get
    return self._get_impl(ident, loading.load_on_ident)
  File "/Users/tao/.virtualenvs/flask/lib/python2.7/site-packages/sqlalchemy/orm/query.py", line 864, in _get_impl
    return fallback_fn(self, key)
  File "/Users/tao/.virtualenvs/flask/lib/python2.7/site-packages/sqlalchemy/orm/loading.py", line 219, in load_on_ident
    return q.one()
  File "/Users/tao/.virtualenvs/flask/lib/python2.7/site-packages/sqlalchemy/orm/query.py", line 2718, in one
    ret = list(self)
  File "/Users/tao/.virtualenvs/flask/lib/python2.7/site-packages/sqlalchemy/orm/query.py", line 2761, in __iter__
    return self._execute_and_instances(context)
  File "/Users/tao/.virtualenvs/flask/lib/python2.7/site-packages/sqlalchemy/orm/query.py", line 2776, in _execute_and_instances
    result = conn.execute(querycontext.statement, self._params)
  File "/Users/tao/.virtualenvs/flask/lib/python2.7/site-packages/sqlalchemy/engine/base.py", line 914, in execute
    return meth(self, multiparams, params)
  File "/Users/tao/.virtualenvs/flask/lib/python2.7/site-packages/sqlalchemy/sql/elements.py", line 323, in _execute_on_connection
    return connection._execute_clauseelement(self, multiparams, params)
  File "/Users/tao/.virtualenvs/flask/lib/python2.7/site-packages/sqlalchemy/engine/base.py", line 1010, in _execute_clauseelement
    compiled_sql, distilled_params
  File "/Users/tao/.virtualenvs/flask/lib/python2.7/site-packages/sqlalchemy/engine/base.py", line 1146, in _execute_context
    context)
  File "/Users/tao/.virtualenvs/flask/lib/python2.7/site-packages/sqlalchemy/engine/base.py", line 1341, in _handle_dbapi_exception
    exc_info
  File "/Users/tao/.virtualenvs/flask/lib/python2.7/site-packages/sqlalchemy/util/compat.py", line 202, in raise_from_cause
    reraise(type(exception), exception, tb=exc_tb, cause=cause)
  File "/Users/tao/.virtualenvs/flask/lib/python2.7/site-packages/sqlalchemy/engine/base.py", line 1139, in _execute_context
    context)
  File "/Users/tao/.virtualenvs/flask/lib/python2.7/site-packages/sqlalchemy/engine/default.py", line 450, in do_execute
    cursor.execute(statement, parameters)
OperationalError: (sqlite3.OperationalError) no such table: user [SQL: u'SELECT user.id AS user_id, user.nickname AS user_nickname, user.email AS user_email, user.about_me AS user_about_me, user.last_seen AS user_last_seen \nFROM user \nWHERE user.id = ?'] [parameters: (2,)]
2016-09-01 09:42:50,271 INFO: microblog startup [in /Users/tao/Study/projects/microblog_flask/app/__init__.py:38]
2016-09-01 09:42:59,420 ERROR: Exception on /index [GET] [in /Users/tao/.virtualenvs/flask/lib/python2.7/site-packages/flask/app.py:1587]
Traceback (most recent call last):
  File "/Users/tao/.virtualenvs/flask/lib/python2.7/site-packages/flask/app.py", line 1988, in wsgi_app
    response = self.full_dispatch_request()
  File "/Users/tao/.virtualenvs/flask/lib/python2.7/site-packages/flask/app.py", line 1641, in full_dispatch_request
    rv = self.handle_user_exception(e)
  File "/Users/tao/.virtualenvs/flask/lib/python2.7/site-packages/flask/app.py", line 1544, in handle_user_exception
    reraise(exc_type, exc_value, tb)
  File "/Users/tao/.virtualenvs/flask/lib/python2.7/site-packages/flask/app.py", line 1637, in full_dispatch_request
    rv = self.preprocess_request()
  File "/Users/tao/.virtualenvs/flask/lib/python2.7/site-packages/flask/app.py", line 1837, in preprocess_request
    rv = func()
  File "/Users/tao/Study/projects/microblog_flask/app/views.py", line 18, in before_request
    if g.user.is_authenticated:
  File "/Users/tao/.virtualenvs/flask/lib/python2.7/site-packages/werkzeug/local.py", line 343, in __getattr__
    return getattr(self._get_current_object(), name)
  File "/Users/tao/.virtualenvs/flask/lib/python2.7/site-packages/werkzeug/local.py", line 302, in _get_current_object
    return self.__local()
  File "/Users/tao/.virtualenvs/flask/lib/python2.7/site-packages/flask_login.py", line 47, in <lambda>
    current_user = LocalProxy(lambda: _get_user())
  File "/Users/tao/.virtualenvs/flask/lib/python2.7/site-packages/flask_login.py", line 858, in _get_user
    current_app.login_manager._load_user()
  File "/Users/tao/.virtualenvs/flask/lib/python2.7/site-packages/flask_login.py", line 389, in _load_user
    return self.reload_user()
  File "/Users/tao/.virtualenvs/flask/lib/python2.7/site-packages/flask_login.py", line 351, in reload_user
    user = self.user_callback(user_id)
  File "/Users/tao/Study/projects/microblog_flask/app/views.py", line 12, in load_user
    return User.query.get(int(id))
  File "/Users/tao/.virtualenvs/flask/lib/python2.7/site-packages/sqlalchemy/orm/query.py", line 831, in get
    return self._get_impl(ident, loading.load_on_ident)
  File "/Users/tao/.virtualenvs/flask/lib/python2.7/site-packages/sqlalchemy/orm/query.py", line 864, in _get_impl
    return fallback_fn(self, key)
  File "/Users/tao/.virtualenvs/flask/lib/python2.7/site-packages/sqlalchemy/orm/loading.py", line 219, in load_on_ident
    return q.one()
  File "/Users/tao/.virtualenvs/flask/lib/python2.7/site-packages/sqlalchemy/orm/query.py", line 2718, in one
    ret = list(self)
  File "/Users/tao/.virtualenvs/flask/lib/python2.7/site-packages/sqlalchemy/orm/query.py", line 2761, in __iter__
    return self._execute_and_instances(context)
  File "/Users/tao/.virtualenvs/flask/lib/python2.7/site-packages/sqlalchemy/orm/query.py", line 2776, in _execute_and_instances
    result = conn.execute(querycontext.statement, self._params)
  File "/Users/tao/.virtualenvs/flask/lib/python2.7/site-packages/sqlalchemy/engine/base.py", line 914, in execute
    return meth(self, multiparams, params)
  File "/Users/tao/.virtualenvs/flask/lib/python2.7/site-packages/sqlalchemy/sql/elements.py", line 323, in _execute_on_connection
    return connection._execute_clauseelement(self, multiparams, params)
  File "/Users/tao/.virtualenvs/flask/lib/python2.7/site-packages/sqlalchemy/engine/base.py", line 1010, in _execute_clauseelement
    compiled_sql, distilled_params
  File "/Users/tao/.virtualenvs/flask/lib/python2.7/site-packages/sqlalchemy/engine/base.py", line 1146, in _execute_context
    context)
  File "/Users/tao/.virtualenvs/flask/lib/python2.7/site-packages/sqlalchemy/engine/base.py", line 1341, in _handle_dbapi_exception
    exc_info
  File "/Users/tao/.virtualenvs/flask/lib/python2.7/site-packages/sqlalchemy/util/compat.py", line 202, in raise_from_cause
    reraise(type(exception), exception, tb=exc_tb, cause=cause)
  File "/Users/tao/.virtualenvs/flask/lib/python2.7/site-packages/sqlalchemy/engine/base.py", line 1139, in _execute_context
    context)
  File "/Users/tao/.virtualenvs/flask/lib/python2.7/site-packages/sqlalchemy/engine/default.py", line 450, in do_execute
    cursor.execute(statement, parameters)
OperationalError: (sqlite3.OperationalError) no such table: user [SQL: u'SELECT user.id AS user_id, user.nickname AS user_nickname, user.email AS user_email, user.about_me AS user_about_me, user.last_seen AS user_last_seen \nFROM user \nWHERE user.id = ?'] [parameters: (2,)]
2016-09-01 09:43:09,507 INFO: microblog startup [in /Users/tao/Study/projects/microblog_flask/app/__init__.py:38]
2016-09-01 09:43:25,604 ERROR: Exception on / [GET] [in /Users/tao/.virtualenvs/flask/lib/python2.7/site-packages/flask/app.py:1587]
Traceback (most recent call last):
  File "/Users/tao/.virtualenvs/flask/lib/python2.7/site-packages/flask/app.py", line 1988, in wsgi_app
    response = self.full_dispatch_request()
  File "/Users/tao/.virtualenvs/flask/lib/python2.7/site-packages/flask/app.py", line 1641, in full_dispatch_request
    rv = self.handle_user_exception(e)
  File "/Users/tao/.virtualenvs/flask/lib/python2.7/site-packages/flask/app.py", line 1544, in handle_user_exception
    reraise(exc_type, exc_value, tb)
  File "/Users/tao/.virtualenvs/flask/lib/python2.7/site-packages/flask/app.py", line 1637, in full_dispatch_request
    rv = self.preprocess_request()
  File "/Users/tao/.virtualenvs/flask/lib/python2.7/site-packages/flask/app.py", line 1837, in preprocess_request
    rv = func()
  File "/Users/tao/Study/projects/microblog_flask/app/views.py", line 18, in before_request
    if g.user.is_authenticated:
  File "/Users/tao/.virtualenvs/flask/lib/python2.7/site-packages/werkzeug/local.py", line 343, in __getattr__
    return getattr(self._get_current_object(), name)
  File "/Users/tao/.virtualenvs/flask/lib/python2.7/site-packages/werkzeug/local.py", line 302, in _get_current_object
    return self.__local()
  File "/Users/tao/.virtualenvs/flask/lib/python2.7/site-packages/flask_login.py", line 47, in <lambda>
    current_user = LocalProxy(lambda: _get_user())
  File "/Users/tao/.virtualenvs/flask/lib/python2.7/site-packages/flask_login.py", line 858, in _get_user
    current_app.login_manager._load_user()
  File "/Users/tao/.virtualenvs/flask/lib/python2.7/site-packages/flask_login.py", line 389, in _load_user
    return self.reload_user()
  File "/Users/tao/.virtualenvs/flask/lib/python2.7/site-packages/flask_login.py", line 351, in reload_user
    user = self.user_callback(user_id)
  File "/Users/tao/Study/projects/microblog_flask/app/views.py", line 12, in load_user
    return User.query.get(int(id))
  File "/Users/tao/.virtualenvs/flask/lib/python2.7/site-packages/sqlalchemy/orm/query.py", line 831, in get
    return self._get_impl(ident, loading.load_on_ident)
  File "/Users/tao/.virtualenvs/flask/lib/python2.7/site-packages/sqlalchemy/orm/query.py", line 864, in _get_impl
    return fallback_fn(self, key)
  File "/Users/tao/.virtualenvs/flask/lib/python2.7/site-packages/sqlalchemy/orm/loading.py", line 219, in load_on_ident
    return q.one()
  File "/Users/tao/.virtualenvs/flask/lib/python2.7/site-packages/sqlalchemy/orm/query.py", line 2718, in one
    ret = list(self)
  File "/Users/tao/.virtualenvs/flask/lib/python2.7/site-packages/sqlalchemy/orm/query.py", line 2761, in __iter__
    return self._execute_and_instances(context)
  File "/Users/tao/.virtualenvs/flask/lib/python2.7/site-packages/sqlalchemy/orm/query.py", line 2776, in _execute_and_instances
    result = conn.execute(querycontext.statement, self._params)
  File "/Users/tao/.virtualenvs/flask/lib/python2.7/site-packages/sqlalchemy/engine/base.py", line 914, in execute
    return meth(self, multiparams, params)
  File "/Users/tao/.virtualenvs/flask/lib/python2.7/site-packages/sqlalchemy/sql/elements.py", line 323, in _execute_on_connection
    return connection._execute_clauseelement(self, multiparams, params)
  File "/Users/tao/.virtualenvs/flask/lib/python2.7/site-packages/sqlalchemy/engine/base.py", line 1010, in _execute_clauseelement
    compiled_sql, distilled_params
  File "/Users/tao/.virtualenvs/flask/lib/python2.7/site-packages/sqlalchemy/engine/base.py", line 1146, in _execute_context
    context)
  File "/Users/tao/.virtualenvs/flask/lib/python2.7/site-packages/sqlalchemy/engine/base.py", line 1341, in _handle_dbapi_exception
    exc_info
  File "/Users/tao/.virtualenvs/flask/lib/python2.7/site-packages/sqlalchemy/util/compat.py", line 202, in raise_from_cause
    reraise(type(exception), exception, tb=exc_tb, cause=cause)
  File "/Users/tao/.virtualenvs/flask/lib/python2.7/site-packages/sqlalchemy/engine/base.py", line 1139, in _execute_context
    context)
  File "/Users/tao/.virtualenvs/flask/lib/python2.7/site-packages/sqlalchemy/engine/default.py", line 450, in do_execute
    cursor.execute(statement, parameters)
OperationalError: (sqlite3.OperationalError) no such table: user [SQL: u'SELECT user.id AS user_id, user.nickname AS user_nickname, user.email AS user_email, user.about_me AS user_about_me, user.last_seen AS user_last_seen \nFROM user \nWHERE user.id = ?'] [parameters: (2,)]
2016-09-01 09:45:29,883 INFO: microblog startup [in /Users/tao/Study/projects/microblog_flask/app/__init__.py:38]
2016-09-01 09:45:51,208 INFO: microblog startup [in /Users/tao/Study/projects/microblog_flask/app/__init__.py:38]
2016-09-01 09:46:07,995 INFO: microblog startup [in /Users/tao/Study/projects/microblog_flask/app/__init__.py:38]
2016-09-01 09:49:10,744 INFO: microblog startup [in /Users/tao/Study/projects/microblog_flask/app/__init__.py:38]
2016-09-01 10:10:53,306 INFO: microblog startup [in /Users/tao/Study/projects/microblog_flask/app/__init__.py:38]
2016-09-01 10:20:55,469 INFO: microblog startup [in /Users/tao/Study/projects/microblog_flask/app/__init__.py:38]
2016-09-01 10:24:33,584 INFO: microblog startup [in /Users/tao/Study/projects/microblog_flask/app/__init__.py:38]
2016-09-01 10:30:14,641 INFO: microblog startup [in /Users/tao/Study/projects/microblog_flask/app/__init__.py:38]
2016-09-01 10:30:21,586 ERROR: Exception on /user/kk/1 [GET] [in /Users/tao/.virtualenvs/flask/lib/python2.7/site-packages/flask/app.py:1587]
Traceback (most recent call last):
  File "/Users/tao/.virtualenvs/flask/lib/python2.7/site-packages/flask/app.py", line 1988, in wsgi_app
    response = self.full_dispatch_request()
  File "/Users/tao/.virtualenvs/flask/lib/python2.7/site-packages/flask/app.py", line 1641, in full_dispatch_request
    rv = self.handle_user_exception(e)
  File "/Users/tao/.virtualenvs/flask/lib/python2.7/site-packages/flask/app.py", line 1544, in handle_user_exception
    reraise(exc_type, exc_value, tb)
  File "/Users/tao/.virtualenvs/flask/lib/python2.7/site-packages/flask/app.py", line 1639, in full_dispatch_request
    rv = self.dispatch_request()
  File "/Users/tao/.virtualenvs/flask/lib/python2.7/site-packages/flask/app.py", line 1625, in dispatch_request
    return self.view_functions[rule.endpoint](**req.view_args)
  File "/Users/tao/.virtualenvs/flask/lib/python2.7/site-packages/flask_login.py", line 792, in decorated_view
    return func(*args, **kwargs)
  File "/Users/tao/Study/projects/microblog_flask/app/views.py", line 112, in user
    posts=posts)
  File "/Users/tao/.virtualenvs/flask/lib/python2.7/site-packages/flask/templating.py", line 134, in render_template
    context, ctx.app)
  File "/Users/tao/.virtualenvs/flask/lib/python2.7/site-packages/flask/templating.py", line 116, in _render
    rv = template.render(context)
  File "/Users/tao/.virtualenvs/flask/lib/python2.7/site-packages/jinja2/environment.py", line 989, in render
    return self.environment.handle_exception(exc_info, True)
  File "/Users/tao/.virtualenvs/flask/lib/python2.7/site-packages/jinja2/environment.py", line 754, in handle_exception
    reraise(exc_type, exc_value, tb)
  File "/Users/tao/Study/projects/microblog_flask/app/templates/user.html", line 2, in top-level template code
    {% extends "base.html" %}
  File "/Users/tao/Study/projects/microblog_flask/app/templates/base.html", line 27, in top-level template code
    {% block content %}{% endblock %}
  File "/Users/tao/Study/projects/microblog_flask/app/templates/user.html", line 25, in block "content"
    {% for post in posts %}
TypeError: 'Pagination' object is not iterable
2016-09-01 10:30:30,102 ERROR: Exception on /user/kk [GET] [in /Users/tao/.virtualenvs/flask/lib/python2.7/site-packages/flask/app.py:1587]
Traceback (most recent call last):
  File "/Users/tao/.virtualenvs/flask/lib/python2.7/site-packages/flask/app.py", line 1988, in wsgi_app
    response = self.full_dispatch_request()
  File "/Users/tao/.virtualenvs/flask/lib/python2.7/site-packages/flask/app.py", line 1641, in full_dispatch_request
    rv = self.handle_user_exception(e)
  File "/Users/tao/.virtualenvs/flask/lib/python2.7/site-packages/flask/app.py", line 1544, in handle_user_exception
    reraise(exc_type, exc_value, tb)
  File "/Users/tao/.virtualenvs/flask/lib/python2.7/site-packages/flask/app.py", line 1639, in full_dispatch_request
    rv = self.dispatch_request()
  File "/Users/tao/.virtualenvs/flask/lib/python2.7/site-packages/flask/app.py", line 1625, in dispatch_request
    return self.view_functions[rule.endpoint](**req.view_args)
  File "/Users/tao/.virtualenvs/flask/lib/python2.7/site-packages/flask_login.py", line 792, in decorated_view
    return func(*args, **kwargs)
  File "/Users/tao/Study/projects/microblog_flask/app/views.py", line 112, in user
    posts=posts)
  File "/Users/tao/.virtualenvs/flask/lib/python2.7/site-packages/flask/templating.py", line 134, in render_template
    context, ctx.app)
  File "/Users/tao/.virtualenvs/flask/lib/python2.7/site-packages/flask/templating.py", line 116, in _render
    rv = template.render(context)
  File "/Users/tao/.virtualenvs/flask/lib/python2.7/site-packages/jinja2/environment.py", line 989, in render
    return self.environment.handle_exception(exc_info, True)
  File "/Users/tao/.virtualenvs/flask/lib/python2.7/site-packages/jinja2/environment.py", line 754, in handle_exception
    reraise(exc_type, exc_value, tb)
  File "/Users/tao/Study/projects/microblog_flask/app/templates/user.html", line 2, in top-level template code
    {% extends "base.html" %}
  File "/Users/tao/Study/projects/microblog_flask/app/templates/base.html", line 27, in top-level template code
    {% block content %}{% endblock %}
  File "/Users/tao/Study/projects/microblog_flask/app/templates/user.html", line 25, in block "content"
    {% for post in posts %}
TypeError: 'Pagination' object is not iterable
2016-09-01 10:30:32,626 ERROR: Exception on /user/kk [GET] [in /Users/tao/.virtualenvs/flask/lib/python2.7/site-packages/flask/app.py:1587]
Traceback (most recent call last):
  File "/Users/tao/.virtualenvs/flask/lib/python2.7/site-packages/flask/app.py", line 1988, in wsgi_app
    response = self.full_dispatch_request()
  File "/Users/tao/.virtualenvs/flask/lib/python2.7/site-packages/flask/app.py", line 1641, in full_dispatch_request
    rv = self.handle_user_exception(e)
  File "/Users/tao/.virtualenvs/flask/lib/python2.7/site-packages/flask/app.py", line 1544, in handle_user_exception
    reraise(exc_type, exc_value, tb)
  File "/Users/tao/.virtualenvs/flask/lib/python2.7/site-packages/flask/app.py", line 1639, in full_dispatch_request
    rv = self.dispatch_request()
  File "/Users/tao/.virtualenvs/flask/lib/python2.7/site-packages/flask/app.py", line 1625, in dispatch_request
    return self.view_functions[rule.endpoint](**req.view_args)
  File "/Users/tao/.virtualenvs/flask/lib/python2.7/site-packages/flask_login.py", line 792, in decorated_view
    return func(*args, **kwargs)
  File "/Users/tao/Study/projects/microblog_flask/app/views.py", line 112, in user
    posts=posts)
  File "/Users/tao/.virtualenvs/flask/lib/python2.7/site-packages/flask/templating.py", line 134, in render_template
    context, ctx.app)
  File "/Users/tao/.virtualenvs/flask/lib/python2.7/site-packages/flask/templating.py", line 116, in _render
    rv = template.render(context)
  File "/Users/tao/.virtualenvs/flask/lib/python2.7/site-packages/jinja2/environment.py", line 989, in render
    return self.environment.handle_exception(exc_info, True)
  File "/Users/tao/.virtualenvs/flask/lib/python2.7/site-packages/jinja2/environment.py", line 754, in handle_exception
    reraise(exc_type, exc_value, tb)
  File "/Users/tao/Study/projects/microblog_flask/app/templates/user.html", line 2, in top-level template code
    {% extends "base.html" %}
  File "/Users/tao/Study/projects/microblog_flask/app/templates/base.html", line 27, in top-level template code
    {% block content %}{% endblock %}
  File "/Users/tao/Study/projects/microblog_flask/app/templates/user.html", line 25, in block "content"
    {% for post in posts %}
TypeError: 'Pagination' object is not iterable
2016-09-01 10:31:50,647 INFO: microblog startup [in /Users/tao/Study/projects/microblog_flask/app/__init__.py:38]
2016-09-01 11:07:32,276 INFO: microblog startup [in /Users/tao/Study/projects/microblog_flask/app/__init__.py:38]
2016-09-01 11:07:40,494 INFO: microblog startup [in /Users/tao/Study/projects/microblog_flask/app/__init__.py:38]
2016-09-01 11:11:48,475 INFO: microblog startup [in app/__init__.py:38]
2016-09-01 11:27:51,324 INFO: microblog startup [in app/__init__.py:38]
2016-09-01 11:58:22,734 INFO: microblog startup [in app/__init__.py:36]
2016-09-01 11:58:57,815 INFO: microblog startup [in app/__init__.py:38]
2016-09-01 12:00:33,679 INFO: microblog startup [in app/__init__.py:38]
2016-09-01 12:01:27,205 INFO: microblog startup [in /Users/tao/Study/projects/microblog_flask/app/__init__.py:38]
2016-09-01 12:19:20,159 INFO: microblog startup [in /Users/tao/Study/projects/microblog_flask/app/__init__.py:38]
2016-09-01 12:19:55,563 INFO: microblog startup [in /Users/tao/Study/projects/microblog_flask/app/__init__.py:38]
